Workbook

Sheet Attendance
A1: وقت | D1: الاسم الأول | E1: عدد الموظفين | F1: اسم الأخير
A2: 46124 | B2: 0.66666667 | D2: احميد راتب | E2: 8 | F2: الادارة
A3: 46124 | B3: 0.33333333 | C3: =(B2-B3)/TIME(8,0,0) -> 1 | D3: احميد راتب | E3: 8 | F3: الادارة
A4: 46124 | B4: 0.66666667 | D4: قابوسة علي | E4: 13 | F4: الادارة
A5: 46124 | B5: 0.33333333 | C5: =(B4-B5)/TIME(8,0,0) -> 1 | D5: قابوسة علي | E5: 13 | F5: الادارة
A6: 46124 | B6: 0.98958333 | D6: ساحة علي | E6: 18 | F6: البراغي مساء
A7: 46124 | B7: 0.65625 | C7: =(B6-B7)/TIME(8,0,0) -> 1 | D7: ساحة علي | E7: 18 | F7: البراغي مساء
A8: 46124 | B8: 0.66666667 | D8: بن سعدية السعيد | E8: 20 | F8: الفيلتاش
A9: 46124 | B9: 0.33333333 | C9: =(B8-B9)/TIME(8,0,0) -> 1 | D9: بن سعدية السعيد | E9: 20 | F9: الفيلتاش
A10: 46124 | B10: 0.66666667 | D10: صبتي محمود التجاني | E10: 21 | F10: الداهن
A11: 46124 | B11: 0.33333333 | C11: =(B10-B11)/TIME(8,0,0) -> 1 | D11: صبتي محمود التجاني | E11: 21 | F11: الداهن
A12: 46124 | B12: 0.98958333 | D12: نويوات شويطر سفيان | E12: 22 | F12: الزنقاج | G12: 0.65625
A13: 46124 | B13: 0.65625 | C13: =(B12-B13)/TIME(8,0,0) -> 1 | D13: نويوات شويطر سفيان | E13: 22 | F13: الزنقاج | G13: 0.33333333 | H13: =(G12-G13)/TIME(1,0,0) -> 7.75
A14: 46124 | B14: 0.66666667 | D14: هقي العروسي | E14: 24 | F14: الفيلتاش | H14: =(G13-G14)/TIME(1,0,0) -> 8
A15: 46124 | B15: 0.33333333 | C15: =(B14-B15)/TIME(8,0,0) -> 1 | D15: هقي العروسي | E15: 24 | F15: الفيلتاش | H15: =(G14-G15)/TIME(1,0,0) -> 0
A16: 46124 | B16: 0.34791667 | D16: شيخة يمينة | E16: 25 | F16: التركيب 2 | H16: =(G15-G16)/TIME(1,0,0) -> 0
A17: 46124 | B17: 0.33333333 | C17: 0.04 | D17: شيخة يمينة | E17: 25 | F17: التركيب 2 | H17: =(G16-G17)/TIME(1,0,0) -> 0
A18: 46124 | B18: 0.67916667 | D18: بن حوة عبد القادر | E18: 26 | F18: البراغي | G18: 0.72083333 | H18: =(G17-G18)/TIME(1,0,0) -> -17.3
A19: 46124 | B19: 0.34583333 | C19: =(B18-B19)/TIME(8,0,0) -> 1 | D19: بن حوة عبد القادر | E19: 26 | F19: البراغي | G19: 0.67916667 | H19: =(G18-G19)/TIME(1,0,0) -> 1
A20: 46124 | B20: 0.66666667 | D20: مدخل هدى | E20: 27 | F20: التركيب 1 | H20: =(G19-G20)/TIME(1,0,0) -> 16.3
A21: 46124 | B21: 0.33333333 | C21: =(B20-B21)/TIME(8,0,0) -> 1 | D21: مدخل هدى | E21: 27 | F21: التركيب 1 | H21: =(G20-G21)/TIME(1,0,0) -> 0
A22: 46124 | B22: 0.66666667 | D22: سالم الياس | E22: 28 | F22: الشبكة | H22: =(G21-G22)/TIME(1,0,0) -> 0
A23: 46124 | B23: 0.33333333 | C23: =(B22-B23)/TIME(8,0,0) -> 1 | D23: سالم الياس | E23: 28 | F23: الشبكة | H23: =(G22-G23)/TIME(1,0,0) -> 0
A24: 46124 | B24: 0.66666667 | D24: جاب الله العربي | E24: 30 | F24: السلك | H24: =(G23-G24)/TIME(1,0,0) -> 0
A25: 46124 | B25: 0.33333333 | C25: =(B24-B25)/TIME(8,0,0) -> 1 | D25: جاب الله العربي | E25: 30 | F25: السلك | H25: =(G24-G25)/TIME(1,0,0) -> 0
A26: 46124 | B26: 0.66666667 | D26: لموشي يوسف | E26: 31 | F26: الفيلتاش | G26: 0.98958333 | H26: =(G25-G26)/TIME(1,0,0) -> -23.75
A27: 46124 | B27: 0.33333333 | C27: =(B26-B27)/TIME(8,0,0) -> 1 | D27: لموشي يوسف | E27: 31 | F27: الفيلتاش | G27: 0.66666667 | H27: =(G26-G27)/TIME(1,0,0) -> 7.75
A28: 46124 | B28: 0.66666667 | D28: بن عبد الله المولدي | E28: 32 | F28: السلك | H28: =(G27-G28)/TIME(1,0,0) -> 16
A29: 46124 | B29: 0.33333333 | C29: =(B28-B29)/TIME(8,0,0) -> 1 | D29: بن عبد الله المولدي | E29: 32 | F29: السلك | H29: =(G28-G29)/TIME(1,0,0) -> 0
A30: 46124 | B30: 0.66666667 | D30: بلهادف عبد الرحمن | E30: 35 | F30: السلك | H30: =(G29-G30)/TIME(1,0,0) -> 0
A31: 46124 | B31: 0.33333333 | C31: =(B30-B31)/TIME(8,0,0) -> 1 | D31: بلهادف عبد الرحمن | E31: 35 | F31: السلك | H31: =(G30-G31)/TIME(1,0,0) -> 0
A32: 46124 | B32: 0.66666667 | D32: شريف احمد | E32: 36 | F32: الكاليبراج | H32: =(G31-G32)/TIME(1,0,0) -> 0
A33: 46124 | B33: 0.33333333 | C33: =(B32-B33)/TIME(8,0,0) -> 1 | D33: شريف احمد | E33: 36 | F33: الكاليبراج | H33: =(G32-G33)/TIME(1,0,0) -> 0
A34: 46124 | B34: 0.66666667 | D34: معوش الصادق | E34: 39 | F34: الدهن | H34: =(G33-G34)/TIME(1,0,0) -> 0
A35: 46124 | B35: 0.33333333 | C35: =(B34-B35)/TIME(8,0,0) -> 1 | D35: معوش الصادق | E35: 39 | F35: الدهن | H35: =(G34-G35)/TIME(1,0,0) -> 0
A36: 46124 | B36: 0.66666667 | D36: تجيني نور الدين | E36: 40 | F36: الدهن | H36: =(G35-G36)/TIME(1,0,0) -> 0
A37: 46124 | B37: 0.33333333 | C37: =(B36-B37)/TIME(8,0,0) -> 1 | D37: تجيني نور الدين | E37: 40 | F37: الدهن | H37: =(G36-G37)/TIME(1,0,0) -> 0
A38: 46124 | B38: 0.66666667 | D38: احميد نعيم | E38: 43 | F38: الكرطون | H38: =(G37-G38)/TIME(1,0,0) -> 0
A39: 46124 | B39: 0.33333333 | C39: =(B38-B39)/TIME(8,0,0) -> 1 | D39: احميد نعيم | E39: 43 | F39: الكرطون | H39: =(G38-G39)/TIME(1,0,0) -> 0
A40: 46124 | B40: 0.66666667 | D40: غريسي ايوب | E40: 44 | F40: الشبكة | H40: =(G39-G40)/TIME(1,0,0) -> 0
...

Sheet Employees
A1: رقم الموظف | B1: اسم الشركة | C1: اسم العامل بالفرنسية | D1: اسم العامل بالعربية
A2: 01 | D2: بوقطاية عزالدين | E2: 1 | F2: 1 | G2: 1 | H2: 1
A3: 02 | D3: مدلل طارق | E3: 1 | F3: 1 | G3: 1 | H3: 1
A4: 04 | B4: allal | C4: Mesai mohammed bachir | D4: مسعي محمد البشير | E4: 1 | F4: 1 | G4: 1 | H4: 1
A5: 06 | B5: allal | C5: Boughettaya Mohamed Anouar | D5: بوقطاية محمد انور | E5: 1 | F5: 1 | G5: 1 | H5: 1
A6: 7 | D6: دهيمي عمار | E6: 1 | F6: 1 | G6: 1 | H6: 0
A7: 8 | B7: allal | C7: Ahmid Rateb | D7: احميد راتب | E7: 1 | F7: 1 | G7: 1 | H7: 1
A8: 10 | D8: شبرو عبد الرحمن | E8: 1 | F8: 1 | G8: 1 | H8: 1
A9: 11 | D9: خليل عبد الحميد | E9: 1 | F9: 1 | G9: 1 | H9: 1
A10: 12 | B10: tpl | C10: Lagoubi Ramzi | D10: العقوبي رمزي | E10: 1 | F10: 1 | G10: 1 | H10: 1
A11: 13 | B11: tpl | C11: Gaboussa Ali | D11: قابوسة علي | E11: 1 | F11: 1 | G11: 1 | H11: 1
A12: 15 | D12: حابي اميرة | E12: 1 | F12: 1 | G12: 1 | H12: 1
A13: 109 | B13: allal | C13: Hammani Mohamed Larouci | D13: حماني محمد العروسي | E13: 0 | F13: 1 | G13: 1 | H13: 0.75
A15: 37 | B15: tpl | C15: Dehimi Mokhtar | D15: دهيمي مختار | E15: 0 | F15: 0 | G15: 0 | H15: 0
A16: 319 | B16: tpl | C16: Debbar Lakhdar | D16: دبار لخضر | E16: 0.72 | F16: 0.78 | G16: 0.35 | H16: 1
A17: 368 | B17: tpl | C17: Dehimi Abdelhafedh | D17: دهيمي عبد الحافظ | E17: 0 | F17: 0 | G17: 0.7 | H17: 0
A18: 380 | B18: allal | C18: Zerbit Mohammed Tahar | D18: زربيط محمد الطاهر | E18: 0.4 | F18: 1 | G18: 0 | H18: 0
A20: 55 | B20: allal | C20: Bouta Soundes | D20: بوته سندس | E20: 1 | F20: 1 | G20: 1 | H20: 1
A21: 94 | B21: allal | C21: Zane Dalal | D21: زان دلال | E21: 1 | F21: 1 | G21: 1 | H21: 1
A23: 266 | B23: tpl | C23: Zouari Ahmed Meriem | D23: زواري احمد مريم | E23: 1 | F23: 1 | G23: 1 | H23: 1
A24: 270 | B24: tpl | C24: Moussaoui Djihad | D24: موساوي جهاد | E24: 1 | F24: 1 | G24: 1 | H24: 1
A25: 286 | B25: allal | C25: Kaddouri Mebarka | D25: قدوري مباركة | E25: 1 | F25: 1 | G25: 1 | H25: 1
A26: 300 | B26: allal | C26: Aroua Fatiha | D26: عروة فتيحة | E26: 1 | F26: 1 | G26: 1 | H26: 1
A28: 38 | B28: tpl | C28: Tedjani Mohammed Tahar | D28: تجاني محمد الطاهر | E28: 1.5 | F28: 1.5 | G28: 1.5 | H28: 1.5
A29: 68 | B29: allal | C29: Saied Sad | D29: سعيد سعد
A30: 69 | B30: tpl | C30: Chikha Mabrouk Khemeis | D30: شيخة مبروك اخميستي | E30: 1.5 | F30: 1.5 | G30: 1.5 | H30: 1.5
A31: 167 | B31: allal | C31: Lebbihi Saad | D31: لبيهي ساعد | E31: 1 | F31: 1 | G31: 1 | H31: 1
A33: 43 | B33: tpl | C33: Ahmid Naim | D33: احميد نعيم | E33: 1 | F33: 1 | G33: 1 | H33: 1
A35: 59 | B35: for | C35: Tedjini Anter | D35: تجيني عنتر | E35: 0.26875 | F35: 0.85 | G35: 1 | H35: 0.87
A36: 82 | B36: innotech | C36: Hebieb Zohra | D36: حبيب الزهرة | E36: 1 | F36: 1 | G36: 1 | H36: 1
A37: 115 | B37: tpl | C37: Mesai Mohammed Brahim | D37: مسعي محمد ابراهيم | E37: 1 | F37: 1 | G37: 1 | H37: 1
A38: 197 | B38: tpl | C38: Mesai Mohamme Ali | D38: مسعي محمد علي 2 | E38: 1 | F38: 1 | G38: 1 | H38: 1
A39: 212 | B39: tpl | C39: Cherifi Hacene | D39: شريفي حسن | E39: 1 | F39: 1 | G39: 1 | H39: 1
A40: 430 | B40: tpl | C40: Acila Brahim | D40: عسيلة ابراهيم | E40: 0 | F40: 0 | G40: 0 | H40: 0
A42: 47 | B42: tpl | C42: Triki Messaoud | D42: تريكي مسعود | E42: 1 | F42: 1 | G42: 1 | H42: 1
A43: 63 | B43: kantal | C43: Mammadi Bachir | D43: ممادي بشير | E43: 0 | F43: 0 | G43: 0 | H43: 0
A44: 70 | D44: سبوعي علي شوقي | E44: 1 | F44: 1 | G44: 1 | H44: 1
A45: 244 | B45: allal | C45: Zennache Lounis | D45: زناش لونيس | E45: 1 | F45: 1 | G45: 1 | H45: 1
A46: 283 | D46: بن قانة محمد | E46: 1 | F46: 1 | G46: 1 | H46: 1
A47: 320 | D47: بن عبد الله عيسى | E47: 1 | F47: 1 | G47: 1 | H47: 1
...

Sheet التسبيقات
B1: مجمع تجاني الصناعي تسبيقات شهرمارس 2026
B3: الادارة
D4: EX | E4: المبلغ 1 | F4: المبلغ 2 | G4: التوقيع
B5: الرقم | C5: الاسم واللقب
B6: =Employees!A2 -> 01 | C6: =Employees!D2 -> بوقطاية عزالدين | D6: =Employees!#REF! -> #REF!
B7: =Employees!A3 -> 02 | C7: =Employees!D3 -> مدلل طارق | D7: =Employees!#REF! -> #REF!
B8: =Employees!A4 -> 04 | C8: =Employees!D4 -> مسعي محمد البشير | D8: =Employees!#REF! -> #REF!
B9: =Employees!A5 -> 06 | C9: =Employees!D5 -> بوقطاية محمد انور | D9: =Employees!#REF! -> #REF!
B10: =Employees!A6 -> 7 | C10: =Employees!D6 -> دهيمي عمار | D10: =Employees!#REF! -> #REF!
B11: =Employees!A7 -> 8 | C11: =Employees!D7 -> احميد راتب | D11: =Employees!#REF! -> #REF!
B12: =Employees!A8 -> 10 | C12: =Employees!D8 -> شبرو عبد الرحمن | D12: =Employees!#REF! -> #REF!
B13: =Employees!A9 -> 11 | C13: =Employees!D9 -> خليل عبد الحميد | D13: =Employees!#REF! -> #REF!
B14: =Employees!A10 -> 12 | C14: =Employees!D10 -> العقوبي رمزي | D14: =Employees!#REF! -> #REF!
B15: =Employees!A11 -> 13 | C15: =Employees!D11 -> قابوسة علي | D15: =Employees!#REF! -> #REF!
B16: =Employees!A12 -> 15 | C16: =Employees!D12 -> حابي اميرة | D16: =Employees!#REF! -> #REF!
B17: =Employees!A13 -> 109 | C17: =Employees!D13 -> حماني محمد العروسي | D17: =Employees!#REF! -> #REF!
B18: ع,مراقبة
D19: EX | E19: المبلغ 1 | F19: المبلغ 2 | G19: التوقيع
B20: الرقم | C20: الاسم واللقب
B21: =Employees!A15 -> 37 | C21: =Employees!D15 -> دهيمي مختار | D21: =Employees!#REF! -> #REF!
B22: =Employees!A16 -> 319 | C22: =Employees!D16 -> دبار لخضر | D22: =Employees!#REF! -> #REF!
B23: =Employees!A17 -> 368 | C23: =Employees!D17 -> دهيمي عبد الحافظ | D23: =Employees!#REF! -> #REF!
B24: =Employees!A18 -> 380 | C24: =Employees!D18 -> زربيط محمد الطاهر | D24: =Employees!#REF! -> #REF!
B25: المخبر
D26: EX | E26: المبلغ 1 | F26: المبلغ 2 | G26: التوقيع
B27: الرقم | C27: الاسم واللقب
B28: =Employees!A20 -> 55 | C28: =Employees!D20 -> بوته سندس | D28: =Employees!#REF! -> #REF!
B29: =Employees!A21 -> 94 | C29: =Employees!D21 -> زان دلال | D29: =Employees!#REF! -> #REF!
B30: المطبخ
D31: EX | E31: المبلغ 1 | F31: المبلغ 2 | G31: التوقيع
B32: الرقم | C32: الاسم واللقب
B33: =Employees!A23 -> 266 | C33: =Employees!D23 -> زواري احمد مريم | D33: =Employees!#REF! -> #REF!
B34: =Employees!A24 -> 270 | C34: =Employees!D24 -> موساوي جهاد | D34: =Employees!#REF! -> #REF!
B35: =Employees!A25 -> 286 | C35: =Employees!D25 -> قدوري مباركة | D35: =Employees!#REF! -> #REF!
B36: =Employees!A26 -> 300 | C36: =Employees!D26 -> عروة فتيحة | D36: =Employees!#REF! -> #REF!
B37: الحراس
D38: EX | E38: المبلغ 1 | F38: المبلغ 2 | G38: التوقيع
B39: الرقم | C39: الاسم واللقب
B40: =Employees!A28 -> 38 | C40: =Employees!D28 -> تجاني محمد الطاهر | D40: =Employees!#REF! -> #REF!
B41: =Employees!A29 -> 68 | C41: =Employees!D29 -> سعيد سعد | D41: =Employees!#REF! -> #REF!
...

Sheet ALLAL
A1: N° | B1: Nom & Prénom | C1: EX

Sheet TPL
A1: N° | B1: Nom & Prénom | C1: EX

Sheet ورقة3
A1: POINTAGE MOIS Janvier 2026 SARL FOR
A2: N° | B2: Nom & Prénom | C2: EX
A7: POINTAGE MOIS Janvier 2026 SARL BTR
A8: N° | B8: Nom & Prénom | C8: EX
A13: POINTAGE MOIS Janvier 2026 SARL VIGEX
A14: N° | B14: Nom & Prénom | C14: EX
A19: POINTAGE MOIS Janvier 2026 SARL KANTAL
A20: N° | B20: Nom & Prénom | C20: EX
A24: POINTAGE MOIS Janvier 2026 SARL INNOTECH
A25: N° | B25: Nom & Prénom | C25: EX

Sheet ورقة1
A1: وقت | B1: الساعة | C1: الحضور | D1: الاسم الأول | E1: عدد الموظفين | F1: اسم الأخير
A2: 46082 | B2: 0.3125 | C2: =(B3-B2)/TIME(7,0,0) -> 1 | D2: احميد احمد التجاني | E2: 107 | F2: الكرطون
A3: 46082 | B3: 0.60416667 | D3: احميد احمد التجاني | E3: 107 | F3: الكرطون
A4: 46082 | B4: 0.3125 | C4: =(B5-B4)/TIME(7,0,0) -> 1 | D4: احميد راتب | E4: 8 | F4: الادارة
A5: 46082 | B5: 0.60416667 | D5: احميد راتب | E5: 8 | F5: الادارة
A6: 46082 | B6: 0.3125 | C6: =(B7-B6)/TIME(7,0,0) -> 1 | D6: احميد نعيم | E6: 43 | F6: الكرطون
A7: 46082 | B7: 0.60416667 | D7: احميد نعيم | E7: 43 | F7: الكرطون
A8: 46082 | B8: 0.20833333 | D8: احويج فارس | E8: 204 | F8: احويج فارس
A9: 46081 | B9: 0.91666667 | C9: =IF(B8<B9,B8+1-B9,B8-B9)/TIME(7,0,0) -> 1 | D9: احويج فارس | E9: 204 | F9: احويج فارس
A10: 46082 | B10: 0.3125 | C10: =(B11-B10)/TIME(7,0,0) -> 1 | D10: العابد عبد الوهاب | E10: 88 | F10: الرفش
A11: 46082 | B11: 0.60416667 | D11: العابد عبد الوهاب | E11: 88 | F11: الرفش
A12: 46082 | B12: 0.3125 | C12: =(B13-B12)/TIME(7,0,0) -> 1 | D12: العقوبي رمزي | E12: 12 | F12: الادارة
A13: 46082 | B13: 0.60416667 | D13: العقوبي رمزي | E13: 12 | F13: الادارة
A14: 46082 | B14: 0.3125 | C14: =(B15-B14)/TIME(7,0,0) -> 1 | D14: بالي عبد الرزاق | E14: 87 | F14: الفيلتاش
A15: 46082 | B15: 0.60416667 | D15: بالي عبد الرزاق | E15: 87 | F15: الفيلتاش
A16: 46082 | B16: 0.20833333 | D16: براهمي عمار | E16: 353 | F16: براهمي عمار
A17: 46081 | B17: 0.91666667 | C17: =IF(B16<B17,B16+1-B17,B16-B17)/TIME(7,0,0) -> 1 | D17: براهمي عمار | E17: 353 | F17: براهمي عمار
A18: 46082 | B18: 0.3125 | C18: =(B19-B18)/TIME(7,0,0) -> 1 | D18: برتيمة عبد الكريم | E18: 290 | F18: البراغي
A19: 46082 | B19: 0.60416667 | D19: برتيمة عبد الكريم | E19: 290 | F19: البراغي
A20: 46082 | B20: 0.3125 | C20: =(B21-B20)/TIME(7,0,0) -> 1 | D20: بركة مسعود | E20: 345 | F20: الزنقاج
A21: 46082 | B21: 0.60416667 | D21: بركة مسعود | E21: 345 | F21: الزنقاج
A22: 46082 | B22: 0.20833333 | D22: بزايدية امير | E22: 105 | F22: بزايدية امير
A23: 46081 | B23: 0.91666667 | C23: =IF(B22<B23,B22+1-B23,B22-B23)/TIME(7,0,0) -> 1 | D23: بزايدية امير | E23: 105 | F23: بزايدية امير
A24: 46082 | B24: 0.3125 | C24: =(B25-B24)/TIME(7,0,0) -> 1 | D24: بشيري علي | E24: 58 | F24: المخزن 2
A25: 46082 | B25: 0.60416667 | D25: بشيري علي | E25: 58 | F25: المخزن 2
A26: 46082 | B26: 0.3125 | C26: =(B27-B26)/TIME(7,0,0) -> 1 | D26: بكوش سعد | E26: 62 | F26: الكرطون
A27: 46082 | B27: 0.60416667 | D27: بكوش سعد | E27: 62 | F27: الكرطون
A28: 46082 | B28: 0.3125 | C28: =(B29-B28)/TIME(7,0,0) -> 1 | D28: بلال عائشة | E28: 124 | F28: التركيب
A29: 46082 | B29: 0.60416667 | D29: بلال عائشة | E29: 124 | F29: التركيب
A30: 46082 | B30: 0.3125 | C30: =(B31-B30)/TIME(7,0,0) -> 1 | D30: بلخضر ساعد | E30: 306 | F30: الشبكة
A31: 46082 | B31: 0.60416667 | D31: بلخضر ساعد | E31: 306 | F31: الشبكة
A32: 46082 | B32: 0.34375 | C32: 0.89 | D32: بله عماد الدين | E32: 402 | F32: التيج فلتي
A33: 46082 | B33: 0.60416667 | D33: بله عماد الدين | E33: 402 | F33: التيج فلتي
A34: 46082 | B34: 0.3125 | C34: =(B35-B34)/TIME(7,0,0) -> 1 | D34: بلهادف عبد الرحمن | E34: 35 | F34: السلك
A35: 46082 | B35: 0.60416667 | D35: بلهادف عبد الرحمن | E35: 35 | F35: السلك
A36: 46082 | B36: 0.20833333 | D36: بن احمد يونس | E36: 143 | F36: بن احمد يونس
A37: 46081 | B37: 0.91666667 | C37: =IF(B36<B37,B36+1-B37,B36-B37)/TIME(7,0,0) -> 1 | D37: بن احمد يونس | E37: 143 | F37: بن احمد يونس
A38: 46082 | B38: 0.3125 | C38: =(B39-B38)/TIME(7,0,0) -> 1 | D38: بن الشهبة عبد العزيز | E38: 275 | F38: الكاليبراج
A39: 46082 | B39: 0.60416667 | D39: بن الشهبة عبد العزيز | E39: 275 | F39: الكاليبراج
A40: 46082 | B40: 0.3125 | C40: =(B41-B40)/TIME(7,0,0) -> 1 | D40: بن بداري عبد الفتاح | E40: 310 | F40: السلسلة
...
